Workbook
Name accounts: Accounts!$A$1:$G$86
Name products: Products!$A$1:$C$8
Name sales_pipeline: Sales_Pipelines!$A$1:$H$8801
Name sales_teams: Sales_teams!$A$1:$C$36

Sheet Analysis
A1: CRM Sales Performance Analysis
A2: B2B Sales Pipeline & Performance Overview | 2017
A4: Won Revenue | B4: =SUM(Sales_Pipelines!H3:H8802) -> 10004480 | C4: Open Pipeline | D4: =SUM(Sales_Pipelines!L2:L8801) -> 85895 | E4: Open Opportunities | F4: =B5 -> 2089 | G4: Avg. Opportunity Value | H4: =B6 -> 2377.3169
A5: Open Opportunities | B5: =COUNTIFS(Sales_Pipelines!E2:E8801,"Prospecting")+COUNTIFS(Sales_Pipelines!E2:E8801,"Engaging") -> 2089
A6: Avg. Open Opportunity Value | B6: =AVERAGEIFS(Sales_Pipelines!J2:J8801,Sales_Pipelines!E2:E8801,"<>Won",Sales_Pipelines!E2:E8801,"<>Lost") -> 2377.3169
A7: Estimated Lost Value (Proxy) | B7: =SUMPRODUCT((Sales_Pipelines!E2:E8801="Lost")*VLOOKUP(Sales_Pipelines!C2:C8801,Products!$A$2:$C$8,3,FALSE)) -> 136015
A9: Deal Stage Performance | E9: Top Sales Agents
A10: Deal Stage | B10: Opportunities | C10: Percentage | E10: Sales Agent | F10: Won Revenue
A11: Prospecting | B11: =COUNTIF(Sales_Pipelines!$E$2:$E$8801,A11) -> 500 | C11: =B11/SUM($B$11:$B$14) -> 0.056818182 | E11: =INDEX(A29:A63,MATCH(F11,B29:B63,0)) -> Darcel Schlecht | F11: =MAX(B32:B66) -> 1153214
A12: Engaging | B12: =COUNTIF(Sales_Pipelines!$E$2:$E$8801,A12) -> 1589 | C12: =B12/SUM($B$11:$B$14) -> 0.18056818 | E12: =INDEX(A32:A66,MATCH(F12,B32:B66,0)) -> Vicki Laflamme | F12: =LARGE(B32:B66,2) -> 478396
A13: Won | B13: =COUNTIF(Sales_Pipelines!$E$2:$E$8801,"Won") -> 4238 | C13: =B13/SUM($B$11:$B$14) -> 0.48159091 | E13: =INDEX(A32:A66,MATCH(F13,B32:B66,0)) -> Kary Hendrixson | F13: =LARGE(B32:B66,3) -> 454298
A14: Lost | B14: =COUNTIF(Sales_Pipelines!$E$2:$E$8801,A14) -> 2473 | C14: =B14/SUM($B$11:$B$14) -> 0.28102273 | E14: =INDEX(A32:A66,MATCH(F14,B32:B66,0)) -> Cassey Cress | F14: =LARGE(B32:B66,4) -> 450489
A15: Closed Win Rate | B15: =COUNTIF(Sales_Pipelines!E2:E8801,"Won")/(COUNTIF(Sales_Pipelines!E2:E8801,"Won")+COUNTIF(Sales_Pipelines!E2:E8801,"Lost")) -> 0.63150052 | E15: =INDEX(A32:A66,MATCH(F15,B32:B66,0)) -> Donn Cantrell | F15: =LARGE(B32:B66,5) -> 445860
A16: Average Won Deal Value | B16: =AVERAGEIFS(Sales_Pipelines!H2:H8801,Sales_Pipelines!E2:E8801,"Won") -> 2360.9094 | E16: =INDEX(A32:A66,MATCH(F16,B32:B66,0)) -> Reed Clapper | F16: =LARGE(B32:B66,6) -> 438336
A19: Product Performance
A20: Product | B20: Won Revenue | C20: Won Opportunities | D20: Total Opportunities | E20: Win Rate | F20: Average Won Deal Value | G20: Estimated Lost Value
A21: GTX Basic | B21: =SUMIFS(Sales_Pipelines!$H$2:$H$8801,Sales_Pipelines!$C$2:$C$8801,A21,Sales_Pipelines!$E$2:$E$8801,"Won") -> 499263 | C21: =COUNTIFS(Sales_Pipelines!$C$2:$C$8801,A21,Sales_Pipelines!$E$2:$E$8801,"Won") -> 915 | D21: =COUNTIF(Sales_Pipelines!$C$2:$C$8801,A21) -> 1866 | E21: =C21/D21 -> 0.4903537 | F21: =IF(C21=0,0,B21/C21) -> 545.64262 | G21: =COUNTIFS(Sales_Pipelines!$C$2:$C$8801,A21,Sales_Pipelines!$E$2:$E$8801,"Lost")*VLOOKUP(A21,Products!$A$2:$C$8,3,FALSE) -> 286550
A22: GTX Pro | B22: =SUMIFS(Sales_Pipelines!$H$2:$H$8801,Sales_Pipelines!$C$2:$C$8801,A22,Sales_Pipelines!$E$2:$E$8801,"Won") -> 3510578 | C22: =COUNTIFS(Sales_Pipelines!$C$2:$C$8801,A22,Sales_Pipelines!$E$2:$E$8801,"Won") -> 729 | D22: =COUNTIF(Sales_Pipelines!$C$2:$C$8801,A22) -> 1480 | E22: =C22/D22 -> 0.49256757 | F22: =IF(C22=0,0,B22/C22) -> 4815.6077 | G22: =COUNTIFS(Sales_Pipelines!$C$2:$C$8801,A22,Sales_Pipelines!$E$2:$E$8801,"Lost")*VLOOKUP(A22,Products!$A$2:$C$8,3,FALSE) -> 2015178
A23: MG Special | B23: =SUMIFS(Sales_Pipelines!$H$2:$H$8801,Sales_Pipelines!$C$2:$C$8801,A23,Sales_Pipelines!$E$2:$E$8801,"Won") -> 43768 | C23: =COUNTIFS(Sales_Pipelines!$C$2:$C$8801,A23,Sales_Pipelines!$E$2:$E$8801,"Won") -> 793 | D23: =COUNTIF(Sales_Pipelines!$C$2:$C$8801,A23) -> 1651 | E23: =C23/D23 -> 0.48031496 | F23: =IF(C23=0,0,B23/C23) -> 55.192938 | G23: =COUNTIFS(Sales_Pipelines!$C$2:$C$8801,A23,Sales_Pipelines!$E$2:$E$8801,"Lost")*VLOOKUP(A23,Products!$A$2:$C$8,3,FALSE) -> 23650
A24: MG Advanced | B24: =SUMIFS(Sales_Pipelines!$H$2:$H$8801,Sales_Pipelines!$C$2:$C$8801,A24,Sales_Pipelines!$E$2:$E$8801,"Won") -> 2216387 | C24: =COUNTIFS(Sales_Pipelines!$C$2:$C$8801,A24,Sales_Pipelines!$E$2:$E$8801,"Won") -> 654 | D24: =COUNTIF(Sales_Pipelines!$C$2:$C$8801,A24) -> 1412 | E24: =C24/D24 -> 0.4631728 | F24: =IF(C24=0,0,B24/C24) -> 3388.9709 | G24: =COUNTIFS(Sales_Pipelines!$C$2:$C$8801,A24,Sales_Pipelines!$E$2:$E$8801,"Lost")*VLOOKUP(A24,Products!$A$2:$C$8,3,FALSE) -> 1458990
A25: GTX Plus Pro | B25: =SUMIFS(Sales_Pipelines!$H$2:$H$8801,Sales_Pipelines!$C$2:$C$8801,A25,Sales_Pipelines!$E$2:$E$8801,"Won") -> 2629651 | C25: =COUNTIFS(Sales_Pipelines!$C$2:$C$8801,A25,Sales_Pipelines!$E$2:$E$8801,"Won") -> 479 | D25: =COUNTIF(Sales_Pipelines!$C$2:$C$8801,A25) -> 968 | E25: =C25/D25 -> 0.49483471 | F25: =IF(C25=0,0,B25/C25) -> 5489.8768 | G25: =COUNTIFS(Sales_Pipelines!$C$2:$C$8801,A25,Sales_Pipelines!$E$2:$E$8801,"Lost")*VLOOKUP(A25,Products!$A$2:$C$8,3,FALSE) -> 1458212
A26: GTX Plus Basic | B26: =SUMIFS(Sales_Pipelines!$H$2:$H$8801,Sales_Pipelines!$C$2:$C$8801,A26,Sales_Pipelines!$E$2:$E$8801,"Won") -> 705275 | C26: =COUNTIFS(Sales_Pipelines!$C$2:$C$8801,A26,Sales_Pipelines!$E$2:$E$8801,"Won") -> 653 | D26: =COUNTIF(Sales_Pipelines!$C$2:$C$8801,A26) -> 1383 | E26: =C26/D26 -> 0.47216197 | F26: =IF(C26=0,0,B26/C26) -> 1080.0536 | G26: =COUNTIFS(Sales_Pipelines!$C$2:$C$8801,A26,Sales_Pipelines!$E$2:$E$8801,"Lost")*VLOOKUP(A26,Products!$A$2:$C$8,3,FALSE) -> 436208
A27: GTK 500 | B27: =SUMIFS(Sales_Pipelines!$H$2:$H$8801,Sales_Pipelines!$C$2:$C$8801,A27,Sales_Pipelines!$E$2:$E$8801,"Won") -> 400612 | C27: =COUNTIFS(Sales_Pipelines!$C$2:$C$8801,A27,Sales_Pipelines!$E$2:$E$8801,"Won") -> 15 | D27: =COUNTIF(Sales_Pipelines!$C$2:$C$8801,A27) -> 40 | E27: =C27/D27 -> 0.375 | F27: =IF(C27=0,0,B27/C27) -> 26707.467 | G27: =COUNTIFS(Sales_Pipelines!$C$2:$C$8801,A27,Sales_Pipelines!$E$2:$E$8801,"Lost")*VLOOKUP(A27,Products!$A$2:$C$8,3,FALSE) -> 267680
A30: Sales Agent Performance
A31: Sales Agent | B31: Won Revenue | C31: Won Opportunities | D31: Total Opportunities | E31: Win Rate | F31: Won Deal Value | G31: Manager | H31: Regional Office
A32: Anna Snelling | B32: =SUMIFS(Sales_Pipelines!$H$2:$H$8801,Sales_Pipelines!$B$2:$B$8801,A32,Sales_Pipelines!$E$2:$E$8801,"Won") -> 275056 | C32: =COUNTIFS(Sales_Pipelines!$B$2:$B$8801,A32,Sales_Pipelines!$E$2:$E$8801,"Won") -> 208 | D32: =COUNTIF(Sales_Pipelines!$B$2:$B$8801,A32) -> 448 | E32: =IF(D32=0,0,C32/D32) -> 0.46428571 | F32: =IF(C32=0,0,B32/C32) -> 1322.3846 | G32: =VLOOKUP(A32,Sales_teams!$A$2:$C$36,2,FALSE) -> Dustin Brinkmann | H32: =VLOOKUP(A32,Sales_teams!$A$2:$C$36,3,FALSE) -> Central
A33: Cecily Lampkin | B33: =SUMIFS(Sales_Pipelines!$H$2:$H$8801,Sales_Pipelines!$B$2:$B$8801,A33,Sales_Pipelines!$E$2:$E$8801,"Won") -> 229800 | C33: =COUNTIFS(Sales_Pipelines!$B$2:$B$8801,A33,Sales_Pipelines!$E$2:$E$8801,"Won") -> 107 | D33: =COUNTIF(Sales_Pipelines!$B$2:$B$8801,A33) -> 203 | E33: =IF(D33=0,0,C33/D33) -> 0.5270936 | F33: =IF(C33=0,0,B33/C33) -> 2147.6636 | G33: =VLOOKUP(A33,Sales_teams!$A$2:$C$36,2,FALSE) -> Dustin Brinkmann | H33: =VLOOKUP(A33,Sales_teams!$A$2:$C$36,3,FALSE) -> Central
A34: Versie Hillebrand | B34: =SUMIFS(Sales_Pipelines!$H$2:$H$8801,Sales_Pipelines!$B$2:$B$8801,A34,Sales_Pipelines!$E$2:$E$8801,"Won") -> 187693 | C34: =COUNTIFS(Sales_Pipelines!$B$2:$B$8801,A34,Sales_Pipelines!$E$2:$E$8801,"Won") -> 176 | D34: =COUNTIF(Sales_Pipelines!$B$2:$B$8801,A34) -> 361 | E34: =IF(D34=0,0,C34/D34) -> 0.48753463 | F34: =IF(C34=0,0,B34/C34) -> 1066.4375 | G34: =VLOOKUP(A34,Sales_teams!$A$2:$C$36,2,FALSE) -> Dustin Brinkmann | H34: =VLOOKUP(A34,Sales_teams!$A$2:$C$36,3,FALSE) -> Central
A35: Lajuana Vencill | B35: =SUMIFS(Sales_Pipelines!$H$2:$H$8801,Sales_Pipelines!$B$2:$B$8801,A35,Sales_Pipelines!$E$2:$E$8801,"Won") -> 194632 | C35: =COUNTIFS(Sales_Pipelines!$B$2:$B$8801,A35,Sales_Pipelines!$E$2:$E$8801,"Won") -> 127 | D35: =COUNTIF(Sales_Pipelines!$B$2:$B$8801,A35) -> 311 | E35: =IF(D35=0,0,C35/D35) -> 0.40836013 | F35: =IF(C35=0,0,B35/C35) -> 1532.5354 | G35: =VLOOKUP(A35,Sales_teams!$A$2:$C$36,2,FALSE) -> Dustin Brinkmann | H35: =VLOOKUP(A35,Sales_teams!$A$2:$C$36,3,FALSE) -> Central
A36: Moses Frase | B36: =SUMIFS(Sales_Pipelines!$H$2:$H$8801,Sales_Pipelines!$B$2:$B$8801,A36,Sales_Pipelines!$E$2:$E$8801,"Won") -> 207182 | C36: =COUNTIFS(Sales_Pipelines!$B$2:$B$8801,A36,Sales_Pipelines!$E$2:$E$8801,"Won") -> 129 | D36: =COUNTIF(Sales_Pipelines!$B$2:$B$8801,A36) -> 260 | E36: =IF(D36=0,0,C36/D36) -> 0.49615385 | F36: =IF(C36=0,0,B36/C36) -> 1606.062 | G36: =VLOOKUP(A36,Sales_teams!$A$2:$C$36,2,FALSE) -> Dustin Brinkmann | H36: =VLOOKUP(A36,Sales_teams!$A$2:$C$36,3,FALSE) -> Central
A37: Jonathan Berthelot | B37: =SUMIFS(Sales_Pipelines!$H$2:$H$8801,Sales_Pipelines!$B$2:$B$8801,A37,Sales_Pipelines!$E$2:$E$8801,"Won") -> 284886 | C37: =COUNTIFS(Sales_Pipelines!$B$2:$B$8801,A37,Sales_Pipelines!$E$2:$E$8801,"Won") -> 171 | D37: =COUNTIF(Sales_Pipelines!$B$2:$B$8801,A37) -> 345 | E37: =IF(D37=0,0,C37/D37) -> 0.49565217 | F37: =IF(C37=0,0,B37/C37) -> 1666 | G37: =VLOOKUP(A37,Sales_teams!$A$2:$C$36,2,FALSE) -> Melvin Marxen | H37: =VLOOKUP(A37,Sales_teams!$A$2:$C$36,3,FALSE) -> Central
A38: Marty Freudenburg | B38: =SUMIFS(Sales_Pipelines!$H$2:$H$8801,Sales_Pipelines!$B$2:$B$8801,A38,Sales_Pipelines!$E$2:$E$8801,"Won") -> 291195 | C38: =COUNTIFS(Sales_Pipelines!$B$2:$B$8801,A38,Sales_Pipelines!$E$2:$E$8801,"Won") -> 122 | D38: =COUNTIF(Sales_Pipelines!$B$2:$B$8801,A38) -> 281 | E38: =IF(D38=0,0,C38/D38) -> 0.4341637 | F38: =IF(C38=0,0,B38/C38) -> 2386.8443 | G38: =VLOOKUP(A38,Sales_teams!$A$2:$C$36,2,FALSE) -> Melvin Marxen | H38: =VLOOKUP(A38,Sales_teams!$A$2:$C$36,3,FALSE) -> Central
A39: Gladys Colclough | B39: =SUMIFS(Sales_Pipelines!$H$2:$H$8801,Sales_Pipelines!$B$2:$B$8801,A39,Sales_Pipelines!$E$2:$E$8801,"Won") -> 345674 | C39: =COUNTIFS(Sales_Pipelines!$B$2:$B$8801,A39,Sales_Pipelines!$E$2:$E$8801,"Won") -> 135 | D39: =COUNTIF(Sales_Pipelines!$B$2:$B$8801,A39) -> 317 | E39: =IF(D39=0,0,C39/D39) -> 0.42586751 | F39: =IF(C39=0,0,B39/C39) -> 2560.5481 | G39: =VLOOKUP(A39,Sales_teams!$A$2:$C$36,2,FALSE) -> Melvin Marxen | H39: =VLOOKUP(A39,Sales_teams!$A$2:$C$36,3,FALSE) -> Central
A40: Niesha Huffines | B40: =SUMIFS(Sales_Pipelines!$H$2:$H$8801,Sales_Pipelines!$B$2:$B$8801,A40,Sales_Pipelines!$E$2:$E$8801,"Won") -> 176961 | C40: =COUNTIFS(Sales_Pipelines!$B$2:$B$8801,A40,Sales_Pipelines!$E$2:$E$8801,"Won") -> 105 | D40: =COUNTIF(Sales_Pipelines!$B$2:$B$8801,A40) -> 239 | E40: =IF(D40=0,0,C40/D40) -> 0.43933054 | F40: =IF(C40=0,0,B40/C40) -> 1685.3429 | G40: =VLOOKUP(A40,Sales_teams!$A$2:$C$36,2,FALSE) -> Melvin Marxen | H40: =VLOOKUP(A40,Sales_teams!$A$2:$C$36,3,FALSE) -> Central
A41: Darcel Schlecht | B41: =SUMIFS(Sales_Pipelines!$H$2:$H$8801,Sales_Pipelines!$B$2:$B$8801,A41,Sales_Pipelines!$E$2:$E$8801,"Won") -> 1153214 | C41: =COUNTIFS(Sales_Pipelines!$B$2:$B$8801,A41,Sales_Pipelines!$E$2:$E$8801,"Won") -> 349 | D41: =COUNTIF(Sales_Pipelines!$B$2:$B$8801,A41) -> 747 | E41: =IF(D41=0,0,C41/D41) -> 0.46720214 | F41: =IF(C41=0,0,B41/C41) -> 3304.3381 | G41: =VLOOKUP(A41,Sales_teams!$A$2:$C$36,2,FALSE) -> Melvin Marxen | H41: =VLOOKUP(A41,Sales_teams!$A$2:$C$36,3,FALSE) -> Central
A42: Mei-Mei Johns | B42: =SUMIFS(Sales_Pipelines!$H$2:$H$8801,Sales_Pipelines!$B$2:$B$8801,A42,Sales_Pipelines!$E$2:$E$8801,"Won") -> 0 | C42: =COUNTIFS(Sales_Pipelines!$B$2:$B$8801,A42,Sales_Pipelines!$E$2:$E$8801,"Won") -> 0 | D42: =COUNTIF(Sales_Pipelines!$B$2:$B$8801,A42) -> 0 | E42: =IF(D42=0,0,C42/D42) -> 0 | F42: =IF(C42=0,0,B42/C42) -> 0 | G42: =VLOOKUP(A42,Sales_teams!$A$2:$C$36,2,FALSE) -> Melvin Marxen | H42: =VLOOKUP(A42,Sales_teams!$A$2:$C$36,3,FALSE) -> Central
A43: Violet Mclelland | B43: =SUMIFS(Sales_Pipelines!$H$2:$H$8801,Sales_Pipelines!$B$2:$B$8801,A43,Sales_Pipelines!$E$2:$E$8801,"Won") -> 123431 | C43: =COUNTIFS(Sales_Pipelines!$B$2:$B$8801,A43,Sales_Pipelines!$E$2:$E$8801,"Won") -> 122 | D43: =COUNTIF(Sales_Pipelines!$B$2:$B$8801,A43) -> 261 | E43: =IF(D43=0,0,C43/D43) -> 0.46743295 | F43: =IF(C43=0,0,B43/C43) -> 1011.7295 | G43: =VLOOKUP(A43,Sales_teams!$A$2:$C$36,2,FALSE) -> Cara Losch | H43: =VLOOKUP(A43,Sales_teams!$A$2:$C$36,3,FALSE) -> East
... A66: Carl Lin | B66: =SUMIFS(Sales_Pipelines!$H$2:$H$8801,Sales_Pipelines!$B$2:$B$8801,A66,Sales_Pipelines!$E$2:$E$8801,"Won") -> 0 | C66: =COUNTIFS(Sales_Pipelines!$B$2:$B$8801,A66,Sales_Pipelines!$E$2:$E$8801,"Won") -> 0 | D66: =COUNTIF(Sales_Pipelines!$B$2:$B$8801,A66) -> 0 | E66: =IF(D66=0,0,C66/D66) -> 0 | F66: =IF(C66=0,0,B66/C66) -> 0 | G66: =VLOOKUP(A66,Sales_teams!$A$2:$C$36,2,FALSE) -> Summer Sewald | H66: =VLOOKUP(A66,Sales_teams!$A$2:$C$36,3,FALSE) -> West
A69: Regional Performance
A70: Regional Office | B70: Won Revenue | C70: Won Opportunities | D70: Total Opportunities | E70: Win Rate | F70: Avg. Won Deal Value
...

Sheet Sales_Pipelines
A1: opportunity_id | B1: sales_agent | C1: product | D1: account | E1: deal_stage | F1: engage_date | G1: close_date | H1: close_value | I1: Unmatched_Product | J1: Expected_Value
A2: 1C1I7A6R | B2: Moses Frase | C2: GTX Plus Basic | D2: Cancity | E2: Won | F2: 42663 | G2: 42795 | H2: 1054 | I2: =IF(COUNTIF(Products!$A$2:$A$8,C2)=0,C2,"") | J2: =IF(OR(E2="Prospecting",E2="Engaging"),VLOOKUP(C2,Products!$A$2:$C$8,3,FALSE),0) -> 0
A3: Z063OYW0 | B3: Darcel Schlecht | C3: GTX Pro | D3: Isdom | E3: Won | F3: 42668 | G3: 42805 | H3: 4514 | I3: =IF(COUNTIF(Products!$A$2:$A$8,C3)=0,C3,"") | J3: =IF(OR(E3="Prospecting",E3="Engaging"),VLOOKUP(C3,Products!$A$2:$C$8,3,FALSE),0) -> 0
A4: EC4QE1BX | B4: Darcel Schlecht | C4: MG Special | D4: Cancity | E4: Won | F4: 42668 | G4: 42801 | H4: 50 | I4: =IF(COUNTIF(Products!$A$2:$A$8,C4)=0,C4,"") | J4: =IF(OR(E4="Prospecting",E4="Engaging"),VLOOKUP(C4,Products!$A$2:$C$8,3,FALSE),0) -> 0
A5: MV1LWRNH | B5: Moses Frase | C5: GTX Basic | D5: Codehow | E5: Won | F5: 42668 | G5: 42803 | H5: 588 | I5: =IF(COUNTIF(Products!$A$2:$A$8,C5)=0,C5,"") | J5: =IF(OR(E5="Prospecting",E5="Engaging"),VLOOKUP(C5,Products!$A$2:$C$8,3,FALSE),0) -> 0 | L5: =MIN(Sales_Pipelines!G2:G8801) -> 42795
A6: PE84CX4O | B6: Zane Levy | C6: GTX Basic | D6: Hatfan | E6: Won | F6: 42668 | G6: 42796 | H6: 517 | I6: =IF(COUNTIF(Products!$A$2:$A$8,C6)=0,C6,"") | J6: =IF(OR(E6="Prospecting",E6="Engaging"),VLOOKUP(C6,Products!$A$2:$C$8,3,FALSE),0) -> 0 | L6: =MAX(Sales_Pipelines!G2:G8801) -> 43100
A7: ZNBS69V1 | B7: Anna Snelling | C7: MG Special | D7: Ron-tech | E7: Won | F7: 42672 | G7: 42795 | H7: 49 | I7: =IF(COUNTIF(Products!$A$2:$A$8,C7)=0,C7,"") | J7: =IF(OR(E7="Prospecting",E7="Engaging"),VLOOKUP(C7,Products!$A$2:$C$8,3,FALSE),0) -> 0
A8: 9ME3374G | B8: Vicki Laflamme | C8: MG Special | D8: J-Texon | E8: Won | F8: 42673 | G8: 42796 | H8: 57 | I8: =IF(COUNTIF(Products!$A$2:$A$8,C8)=0,C8,"") | J8: =IF(OR(E8="Prospecting",E8="Engaging"),VLOOKUP(C8,Products!$A$2:$C$8,3,FALSE),0) -> 0
A9: 7GN8Q4LL | B9: Markita Hansen | C9: GTX Basic | D9: Cheers | E9: Won | F9: 42675 | G9: 42801 | H9: 601 | I9: =IF(COUNTIF(Products!$A$2:$A$8,C9)=0,C9,"") | J9: =IF(OR(E9="Prospecting",E9="Engaging"),VLOOKUP(C9,Products!$A$2:$C$8,3,FALSE),0) -> 0
A10: OLK9LKZB | B10: Niesha Huffines | C10: GTX Plus Basic | D10: Zumgoity | E10: Won | F10: 42675 | G10: 42797 | H10: 1026 | I10: =IF(COUNTIF(Products!$A$2:$A$8,C10)=0,C10,"") | J10: =IF(OR(E10="Prospecting",E10="Engaging"),VLOOKUP(C10,Products!$A$2:$C$8,3,FALSE),0) -> 0
A11: HAXMC4IX | B11: James Ascencio | C11: MG Advanced | E11: Engaging | F11: 42677 | I11: =IF(COUNTIF(Products!$A$2:$A$8,C11)=0,C11,"") | J11: =IF(OR(E11="Prospecting",E11="Engaging"),VLOOKUP(C11,Products!$A$2:$C$8,3,FALSE),0) -> 3393
A12: NL3JZH1Z | B12: Anna Snelling | C12: MG Special | D12: Bioholding | E12: Won | F12: 42678 | G12: 42804 | H12: 53 | I12: =IF(COUNTIF(Products!$A$2:$A$8,C12)=0,C12,"") | J12: =IF(OR(E12="Prospecting",E12="Engaging"),VLOOKUP(C12,Products!$A$2:$C$8,3,FALSE),0) -> 0
A13: KWVA7VR1 | B13: Gladys Colclough | C13: GTX Pro | D13: Genco Pura Olive Oil Company | E13: Lost | F13: 42678 | G13: 42812 | H13: 0 | I13: =IF(COUNTIF(Products!$A$2:$A$8,C13)=0,C13,"") | J13: =IF(OR(E13="Prospecting",E13="Engaging"),VLOOKUP(C13,Products!$A$2:$C$8,3,FALSE),0) -> 0
A14: S8DX3XOU | B14: James Ascencio | C14: GTX Plus Pro | D14: Sunnamplex | E14: Won | F14: 42678 | G14: 42804 | H14: 5169 | I14: =IF(COUNTIF(Products!$A$2:$A$8,C14)=0,C14,"") | J14: =IF(OR(E14="Prospecting",E14="Engaging"),VLOOKUP(C14,Products!$A$2:$C$8,3,FALSE),0) -> 0
A15: ENB2XD8G | B15: Maureen Marcano | C15: GTX Plus Pro | D15: Sonron | E15: Won | F15: 42678 | G15: 42800 | H15: 4631 | I15: =IF(COUNTIF(Products!$A$2:$A$8,C15)=0,C15,"") | J15: =IF(OR(E15="Prospecting",E15="Engaging"),VLOOKUP(C15,Products!$A$2:$C$8,3,FALSE),0) -> 0
A16: 09YE9QOV | B16: Hayden Neloms | C16: MG Advanced | D16: Finjob | E16: Won | F16: 42679 | G16: 42805 | H16: 3393 | I16: =IF(COUNTIF(Products!$A$2:$A$8,C16)=0,C16,"") | J16: =IF(OR(E16="Prospecting",E16="Engaging"),VLOOKUP(C16,Products!$A$2:$C$8,3,FALSE),0) -> 0
A17: 3F5MZNEH | B17: Rosalina Dieter | C17: MG Special | D17: Sonron | E17: Lost | F17: 42679 | G17: 42797 | H17: 0 | I17: =IF(COUNTIF(Products!$A$2:$A$8,C17)=0,C17,"") | J17: =IF(OR(E17="Prospecting",E17="Engaging"),VLOOKUP(C17,Products!$A$2:$C$8,3,FALSE),0) -> 0
A18: M6WEJXC0 | B18: Rosalina Dieter | C18: MG Advanced | D18: Scotfind | E18: Won | F18: 42679 | G18: 42800 | H18: 3284 | I18: =IF(COUNTIF(Products!$A$2:$A$8,C18)=0,C18,"") | J18: =IF(OR(E18="Prospecting",E18="Engaging"),VLOOKUP(C18,Products!$A$2:$C$8,3,FALSE),0) -> 0
A19: 6PTR7VBR | B19: Versie Hillebrand | C19: MG Special | D19: Treequote | E19: Won | F19: 42680 | G19: 42799 | H19: 61 | I19: =IF(COUNTIF(Products!$A$2:$A$8,C19)=0,C19,"") | J19: =IF(OR(E19="Prospecting",E19="Engaging"),VLOOKUP(C19,Products!$A$2:$C$8,3,FALSE),0) -> 0
A20: 902REDPA | B20: Daniell Hammack | C20: GTX Pro | D20: Xx-zobam | E20: Lost | F20: 42681 | G20: 42803 | H20: 0 | I20: =IF(COUNTIF(Products!$A$2:$A$8,C20)=0,C20,"") | J20: =IF(OR(E20="Prospecting",E20="Engaging"),VLOOKUP(C20,Products!$A$2:$C$8,3,FALSE),0) -> 0
A21: 5J9CMGDV | B21: Elease Gluck | C21: MG Special | D21: Rantouch | E21: Won | F21: 42681 | G21: 42802 | H21: 46 | I21: =IF(COUNTIF(Products!$A$2:$A$8,C21)=0,C21,"") | J21: =IF(OR(E21="Prospecting",E21="Engaging"),VLOOKUP(C21,Products!$A$2:$C$8,3,FALSE),0) -> 0
A22: JJXRR8R6 | B22: James Ascencio | C22: GTX Plus Pro | D22: Fasehatice | E22: Lost | F22: 42681 | G22: 42811 | H22: 0 | I22: =IF(COUNTIF(Products!$A$2:$A$8,C22)=0,C22,"") | J22: =IF(OR(E22="Prospecting",E22="Engaging"),VLOOKUP(C22,Products!$A$2:$C$8,3,FALSE),0) -> 0
A23: WF4HA5NW | B23: Moses Frase | C23: MG Special | D23: Ron-tech | E23: Won | F23: 42681 | G23: 42812 | H23: 50 | I23: =IF(COUNTIF(Products!$A$2:$A$8,C23)=0,C23,"") | J23: =IF(OR(E23="Prospecting",E23="Engaging"),VLOOKUP(C23,Products!$A$2:$C$8,3,FALSE),0) -> 0
... A26: SBCR987L | B26: Kami Bicknell | C26: GTX Basic | D26: Zoomit | E26: Won | F26: 42684 | G26: 42817 | H26: 590 | I26: =IF(COUNTIF(Products!$A$2:$A$8,C26)=0,C26,"") | J26: =IF(OR(E26="Prospecting",E26="Engaging"),VLOOKUP(C26,Products!$A$2:$C$8,3,FALSE),0) -> 0
A27: UP409DSB | B27: Maureen Marcano | C27: MG Advanced | D27: Ganjaflex | E27: Engaging | F27: 42684 | I27: =IF(COUNTIF(Products!$A$2:$A$8,C27)=0,C27,"") | J27: =IF(OR(E27="Prospecting",E27="Engaging"),VLOOKUP(C27,Products!$A$2:$C$8,3,FALSE),0) -> 3393
A28: JSD4APT2 | B28: Versie Hillebrand | C28: MG Special | D28: Bioholding | E28: Won | F28: 42684 | G28: 42806 | H28: 61 | I28: =IF(COUNTIF(Products!$A$2:$A$8,C28)=0,C28,"") | J28: =IF(OR(E28="Prospecting",E28="Engaging"),VLOOKUP(C28,Products!$A$2:$C$8,3,FALSE),0) -> 0
A29: AO9Z2D17 | B29: Violet Mclelland | C29: GTX Plus Pro | D29: Xx-zobam | E29: Lost | F29: 42684 | G29: 42805 | H29: 0 | I29: =IF(COUNTIF(Products!$A$2:$A$8,C29)=0,C29,"") | J29: =IF(OR(E29="Prospecting",E29="Engaging"),VLOOKUP(C29,Products!$A$2:$C$8,3,FALSE),0) -> 0
A30: 5M58DTJK | B30: Elease Gluck | C30: MG Special | D30: Cheers | E30: Won | F30: 42685 | G30: 42799 | H30: 58 | I30: =IF(COUNTIF(Products!$A$2:$A$8,C30)=0,C30,"") | J30: =IF(OR(E30="Prospecting",E30="Engaging"),VLOOKUP(C30,Products!$A$2:$C$8,3,FALSE),0) -> 0
A31: KNY1OSAB | B31: Maureen Marcano | C31: GTX Pro | D31: Labdrill | E31: Won | F31: 42685 | G31: 42808 | H31: 4899 | I31: =IF(COUNTIF(Products!$A$2:$A$8,C31)=0,C31,"") | J31: =IF(OR(E31="Prospecting",E31="Engaging"),VLOOKUP(C31,Products!$A$2:$C$8,3,FALSE),0) -> 0
A32: EAZDUUM9 | B32: Rosie Papadopoulos | C32: MG Advanced | D32: Zotware | E32: Lost | F32: 42685 | G32: 42795 | H32: 0 | I32: =IF(COUNTIF(Products!$A$2:$A$8,C32)=0,C32,"") | J32: =IF(OR(E32="Prospecting",E32="Engaging"),VLOOKUP(C32,Products!$A$2:$C$8,3,FALSE),0) -> 0
A33: 2STUSOFE | B33: Versie Hillebrand | C33: MG Special | D33: dambase | E33: Won | F33: 42685 | G33: 42797 | H33: 67 | I33: =IF(COUNTIF(Products!$A$2:$A$8,C33)=0,C33,"") | J33: =IF(OR(E33="Prospecting",E33="Engaging"),VLOOKUP(C33,Products!$A$2:$C$8,3,FALSE),0) -> 0
A34: JYKM0B00 | B34: James Ascencio | C34: GTX Pro | D34: Xx-holding | E34: Won | F34: 42686 | G34: 42800 | H34: 4338 | I34: =IF(COUNTIF(Products!$A$2:$A$8,C34)=0,C34,"") | J34: =IF(OR(E34="Prospecting",E34="Engaging"),VLOOKUP(C34,Products!$A$2:$C$8,3,FALSE),0) -> 0
A35: KU28360J | B35: Kary Hendrixson | C35: GTX Basic | D35: Fasehatice | E35: Won | F35: 42686 | G35: 42813 | H35: 578 | I35: =IF(COUNTIF(Products!$A$2:$A$8,C35)=0,C35,"") | J35: =IF(OR(E35="Prospecting",E35="Engaging"),VLOOKUP(C35,Products!$A$2:$C$8,3,FALSE),0) -> 0
A36: N4SD17JR | B36: Reed Clapper | C36: GTX Basic | D36: Acme Corporation | E36: Won | F36: 42686 | G36: 42795 | H36: 556 | I36: =IF(COUNTIF(Products!$A$2:$A$8,C36)=0,C36,"") | J36: =IF(OR(E36="Prospecting",E36="Engaging"),VLOOKUP(C36,Products!$A$2:$C$8,3,FALSE),0) -> 0
A37: E67P9Y3Q | B37: Rosalina Dieter | C37: GTX Basic | D37: Green-Plus | E37: Won | F37: 42686 | G37: 42797 | H37: 635 | I37: =IF(COUNTIF(Products!$A$2:$A$8,C37)=0,C37,"") | J37: =IF(OR(E37="Prospecting",E37="Engaging"),VLOOKUP(C37,Products!$A$2:$C$8,3,FALSE),0) -> 0
A38: AT3MMVIS | B38: Wilburn Farren | C38: MG Advanced | D38: The New York Inquirer | E38: Won | F38: 42686 | G38: 42801 | H38: 3045 | I38: =IF(COUNTIF(Products!$A$2:$A$8,C38)=0,C38,"") | J38: =IF(OR(E38="Prospecting",E38="Engaging"),VLOOKUP(C38,Products!$A$2:$C$8,3,FALSE),0) -> 0
A39: REJ11LRY | B39: Garret Kinder | C39: GTX Plus Basic | D39: Mathtouch | E39: Won | F39: 42687 | G39: 42808 | H39: 1233 | I39: =IF(COUNTIF(Products!$A$2:$A$8,C39)=0,C39,"") | J39: =IF(OR(E39="Prospecting",E39="Engaging"),VLOOKUP(C39,Products!$A$2:$C$8,3,FALSE),0) -> 0
... A43: CZVN09WN | B43: Darcel Schlecht | C43: GTX Plus Basic | D43: Konmatfix | E43: Won | F43: 42688 | G43: 42814 | H43: 1170 | I43: =IF(COUNTIF(Products!$A$2:$A$8,C43)=0,C43,"") | J43: =IF(OR(E43="Prospecting",E43="Engaging"),VLOOKUP(C43,Products!$A$2:$C$8,3,FALSE),0) -> 0
A44: EG7OFLFR | B44: Kami Bicknell | C44: GTX Basic | E44: Engaging | F44: 42688 | I44: =IF(COUNTIF(Products!$A$2:$A$8,C44)=0,C44,"") | J44: =IF(OR(E44="Prospecting",E44="Engaging"),VLOOKUP(C44,Products!$A$2:$C$8,3,FALSE),0) -> 550
A45: 30UQWUKB | B45: Marty Freudenburg | C45: GTX Plus Basic | D45: Genco Pura Olive Oil Company | E45: Won | F45: 42689 | G45: 42814 | H45: 1162 | I45: =IF(COUNTIF(Products!$A$2:$A$8,C45)=0,C45,"") | J45: =IF(OR(E45="Prospecting",E45="Engaging"),VLOOKUP(C45,Products!$A$2:$C$8,3,FALSE),0) -> 0
...

Sheet Accounts
A1: account | B1: sector | C1: year_established | D1: revenue | E1: employees | F1: office_location | G1: subsidiary_of
A2: Acme Corporation | B2: technolgy | C2: 1996 | D2: 1100.04 | E2: 2822 | F2: United States
A3: Betasoloin | B3: medical | C3: 1999 | D3: 251.41 | E3: 495 | F3: United States
A4: Betatech | B4: medical | C4: 1986 | D4: 647.18 | E4: 1185 | F4: Kenya
A5: Bioholding | B5: medical | C5: 2012 | D5: 587.34 | E5: 1356 | F5: Philipines
A6: Bioplex | B6: medical | C6: 1991 | D6: 326.82 | E6: 1016 | F6: United States
A7: Blackzim | B7: retail | C7: 2009 | D7: 497.11 | E7: 1588 | F7: United States
A8: Bluth Company | B8: technolgy | C8: 1993 | D8: 1242.32 | E8: 3027 | F8: United States | G8: Acme Corporation
A9: Bubba Gump | B9: software | C9: 2002 | D9: 987.39 | E9: 2253 | F9: United States
A10: Cancity | B10: retail | C10: 2001 | D10: 718.62 | E10: 2448 | F10: United States
A11: Cheers | B11: entertainment | C11: 1993 | D11: 4269.9 | E11: 6472 | F11: United States | G11: Massive Dynamic
A12: Codehow | B12: software | C12: 1998 | D12: 2714.9 | E12: 2641 | F12: United States | G12: Acme Corporation
A13: Condax | B13: medical | C13: 2017 | D13: 4.54 | E13: 9 | F13: United States
A14: Conecom | B14: technolgy | C14: 2005 | D14: 1520.66 | E14: 1806 | F14: United States
A15: Dalttechnology | B15: software | C15: 2013 | D15: 98.79 | E15: 96 | F15: United States | G15: Bubba Gump
A16: dambase | B16: marketing | C16: 1995 | D16: 2173.98 | E16: 2928 | F16: United States | G16: Inity
A17: Domzoom | B17: entertainment | C17: 1998 | D17: 217.87 | E17: 551 | F17: United States
A18: Doncon | B18: technolgy | C18: 2010 | D18: 587.72 | E18: 1501 | F18: United States
A19: Donquadtech | B19: technolgy | C19: 1992 | D19: 1712.68 | E19: 3194 | F19: United States | G19: Acme Corporation
A20: Dontechi | B20: software | C20: 1982 | D20: 4618 | E20: 10083 | F20: United States
A21: Donware | B21: marketing | C21: 1999 | D21: 1197.44 | E21: 2570 | F21: United States
A22: Fasehatice | B22: retail | C22: 1990 | D22: 4968.91 | E22: 7523 | F22: United States
A23: Faxquote | B23: telecommunications | C23: 1995 | D23: 1825.82 | E23: 5595 | F23: United States | G23: Sonron
A24: Finhigh | B24: finance | C24: 2006 | D24: 1102.43 | E24: 1759 | F24: United States
A25: Finjob | B25: employment | C25: 1988 | D25: 2059.9 | E25: 3644 | F25: United States
A26: Funholding | B26: finance | C26: 1991 | D26: 2819.5 | E26: 7227 | F26: United States | G26: Golddex
A27: Ganjaflex | B27: retail | C27: 1995 | D27: 5158.71 | E27: 17479 | F27: Japan
A28: Gekko & Co | B28: retail | C28: 1990 | D28: 2520.83 | E28: 3502 | F28: United States
A29: Genco Pura Olive Oil Company | B29: retail | C29: 2007 | D29: 894.33 | E29: 1635 | F29: Italy
A30: Globex Corporation | B30: technolgy | C30: 2000 | D30: 1223.72 | E30: 2497 | F30: Norway
A31: Gogozoom | B31: telecommunications | C31: 2007 | D31: 86.68 | E31: 187 | F31: United States | G31: Sonron
A32: Golddex | B32: finance | C32: 2008 | D32: 52.5 | E32: 165 | F32: United States
A33: Goodsilron | B33: marketing | C33: 2000 | D33: 2952.73 | E33: 5107 | F33: United States
A34: Green-Plus | B34: services | C34: 2003 | D34: 692.19 | E34: 1922 | F34: United States
A35: Groovestreet | B35: retail | C35: 2003 | D35: 223.8 | E35: 299 | F35: United States
A36: Hatfan | B36: services | C36: 1982 | D36: 792.46 | E36: 1299 | F36: United States
A37: Hottechi | B37: technolgy | C37: 1997 | D37: 8170.38 | E37: 16499 | F37: Korea
A38: Initech | B38: telecommunications | C38: 1994 | D38: 6395.05 | E38: 20275 | F38: United States
A39: Inity | B39: marketing | C39: 1986 | D39: 2403.58 | E39: 8801 | F39: United States
A40: Isdom | B40: medical | C40: 2002 | D40: 3178.24 | E40: 4540 | F40: United States
...

Sheet Sales_teams
A1: sales_agent | B1: manager | C1: regional_office
A2: Anna Snelling | B2: Dustin Brinkmann | C2: Central
A3: Cecily Lampkin | B3: Dustin Brinkmann | C3: Central
A4: Versie Hillebrand | B4: Dustin Brinkmann | C4: Central
A5: Lajuana Vencill | B5: Dustin Brinkmann | C5: Central
A6: Moses Frase | B6: Dustin Brinkmann | C6: Central
A7: Jonathan Berthelot | B7: Melvin Marxen | C7: Central
A8: Marty Freudenburg | B8: Melvin Marxen | C8: Central
A9: Gladys Colclough | B9: Melvin Marxen | C9: Central
A10: Niesha Huffines | B10: Melvin Marxen | C10: Central
A11: Darcel Schlecht | B11: Melvin Marxen | C11: Central
A12: Mei-Mei Johns | B12: Melvin Marxen | C12: Central
... A36: Carl Lin | B36: Summer Sewald | C36: West

Sheet Products
A1: product | B1: series | C1: sales_price
A2: GTX Basic | B2: GTX | C2: 550
A3: GTX Pro | B3: GTX | C3: 4821
A4: MG Special | B4: MG | C4: 55
A5: MG Advanced | B5: MG | C5: 3393
A6: GTX Plus Pro | B6: GTX | C6: 5482
A7: GTX Plus Basic | B7: GTX | C7: 1096
A8: GTK 500 | B8: GTK | C8: 26768
